<?xml version="1.0" encoding="utf-8"?>
<robot name="mobile_base" xmlns:xacro="http://ros.org/wiki/xacro">
    <xacro:macro name="mobile_base">
        <link name="base_link">
            <visual>
                <geometry>
                    <mesh filename="package://spesbot_description/urdf/meshes/mobile_base.stl" />
                </geometry>
            </visual>
            <collision>
                <origin xyz="-0.15 0 0" rpy="0 0 0" />
                <geometry>
                    <box size="0.4 0.3 0.02" />
                </geometry>
            </collision>
            <inertial>
                <mass value="5.0" />
                <origin xyz="0 0 0" rpy="0 0 0" />
                <inertia ixx="0.1" ixy="0" ixz="0" iyy="0.1" iyz="0" izz="0.1" />
            </inertial>
        </link>
        <joint name="left_motor" type="continuous">
            <parent link="base_link" />
            <child link="left_wheel_link" />
            <origin xyz="0 0.145 0" rpy="0 0 0" />
            <axis xyz="0 1 0" />
        </joint>
        <link name="left_wheel_link">
            <visual>
                <geometry>
                    <mesh filename="package://spesbot_description/urdf/meshes/wheel.stl" />
                </geometry>
            </visual>
            <collision>
                <origin xyz="0 0.03 0" rpy="1.5707 0 0" />
                <geometry>
                    <cylinder radius="0.085" length="0.03" />
                </geometry>
            </collision>
            <inertial>
                <mass value="2.0" />
                <origin xyz="0 0 0" rpy="0 0 0" />
                <inertia ixx="0.0001" ixy="0" ixz="0" iyy="0.0001" iyz="0" izz="0.0001" />
            </inertial>
        </link>
        <joint name="right_motor" type="continuous">
            <parent link="base_link" />
            <child link="right_wheel_link" />
            <origin xyz="0 -0.145 0" rpy="0 0 0" />
            <axis xyz="0 1 0" />
        </joint>
        <link name="right_wheel_link">
            <visual>
                <geometry>
                    <mesh
                        filename="package://spesbot_description/urdf/meshes/wheel.stl" />
                </geometry>
                <origin xyz="0 0 0" rpy="0 0 3.14159" />
            </visual>
            <collision>
                <origin xyz="0 -0.03 0" rpy="1.5707 0 0" />
                <geometry>
                    <cylinder radius="0.085" length="0.03" />
                </geometry>
            </collision>
            <inertial>
                <mass value="2.0" />
                <origin xyz="0 0 0" rpy="0 0 0" />
                <inertia ixx="0.0001" ixy="0" ixz="0" iyy="0.0001" iyz="0" izz="0.0001" />
            </inertial>
        </link>
        <joint name="caster_steering_joint" type="continuous">
            <parent link="base_link" />
            <child link="caster_holder_link" />
            <origin xyz="-0.31 0 0" rpy="0 0 0" />
            <axis xyz="0 0 1" />
        </joint>
        <link name="caster_holder_link">
            <visual>
                <geometry>
                    <mesh
                        filename="package://spesbot_description/urdf/meshes/caster_holder.stl" />
                </geometry>
            </visual>
            <collision>
                <origin xyz="0 0 0" rpy="0 0 0" />
                <geometry>
                    <cylinder radius="0.03" length="0.01" />
                </geometry>
            </collision>
            <inertial>
                <mass value="0.3" />
                <origin xyz="0 0 0" rpy="0 0 0" />
                <inertia ixx="0.0001" ixy="0" ixz="0" iyy="0.0001" iyz="0" izz="0.0001" />
            </inertial>
        </link>
        <joint name="caster_wheel_joint" type="continuous">
            <parent link="caster_holder_link" />
            <child link="caster_wheel_link" />
            <origin xyz="-0.03 0 -0.05" rpy="0 0 0" />
            <axis xyz="0 1 0" />
        </joint>
        <link name="caster_wheel_link">
            <visual>
                <geometry>
                    <mesh
                        filename="package://spesbot_description/urdf/meshes/caster_wheel.stl" />
                </geometry>
            </visual>
            <collision>
                <origin xyz="0 0 0" rpy="1.5707 0 0" />
                <geometry>
                    <cylinder radius="0.033" length="0.03" />
                </geometry>
            </collision>
            <inertial>
                <mass value="2.0" />
                <origin xyz="0 0 0" rpy="0 0 0" />
                <inertia ixx="0.0001" ixy="0" ixz="0" iyy="0.0001" iyz="0" izz="0.0001" />
            </inertial>
        </link>
    </xacro:macro>
</robot>