#VRML_SIM R2023b utf8
# license: Apache License 2.0
# license url: http://www.apache.org/licenses/LICENSE-2.0
# This is a proto file for Webots for the SpesBot
# Extracted from a URDF content string

PROTO SpesBot [
  field  SFVec3f     translation     0 0 0
  field  SFRotation  rotation        0 0 1 0
  field  SFString    name            "SpesBot"  # Is `Robot.name`.
  field  SFString    controller      "void"     # Is `Robot.controller`.
  field  MFString    controllerArgs  []         # Is `Robot.controllerArgs`.
  field  SFString    customData      ""         # Is `Robot.customData`.
  field  SFBool      supervisor      FALSE      # Is `Robot.supervisor`.
  field  SFBool      synchronization TRUE       # Is `Robot.synchronization`.
  field  SFBool      selfCollision   FALSE      # Is `Robot.selfCollision`.
  field  MFNode      toolSlot        []         # Extend the robot with new nodes at the end of the arm.
]
{
  Robot {
    translation IS translation
    rotation IS rotation
    controller IS controller
    controllerArgs IS controllerArgs
    customData IS customData
    supervisor IS supervisor
    synchronization IS synchronization
    selfCollision IS selfCollision
    children [
      Shape {
        appearance PBRAppearance {
          baseColor 0.500000 0.500000 0.500000
          roughness 1.000000
          metalness 0
        }
        geometry DEF mobile_base Mesh {
          url "/spesbot/ros2_ws/install/spesbot_description/share/spesbot_description/urdf/meshes/mobile_base.stl"
        }
      }
      HingeJoint {
        jointParameters HingeJointParameters {
          axis 0.000000 1.000000 0.000000
          anchor 0.000000 0.145000 0.000000
        }
        device [
          RotationalMotor {
            name "left_motor"
            maxTorque 10000
          }
          PositionSensor {
            name "left_motor_sensor"
          }
        ]
        endPoint Solid {
          translation 0.000000 0.145000 0.000000
          children [
            Shape {
              appearance PBRAppearance {
                baseColor 0.500000 0.500000 0.500000
                roughness 1.000000
                metalness 0
              }
              geometry DEF wheel Mesh {
                url "/spesbot/ros2_ws/install/spesbot_description/share/spesbot_description/urdf/meshes/wheel.stl"
              }
            }
          ]
          name "left_wheel_link"
          boundingObject Pose {
            translation 0.000000 0.030000 0.000000
            rotation 1.000000 0.000000 0.000000 1.570700
            children [
              Cylinder {
                radius 0.085
                height 0.03
              }
            ]
          }
          physics Physics {
            density -1
            mass 2.000000
            centerOfMass [ 0.000000 0.000000 0.000000 ]
            inertiaMatrix [
              1.000000e-04 1.000000e-04 1.000000e-04
              0.000000e+00 0.000000e+00 0.000000e+00
            ]
          }
        }
      }
      HingeJoint {
        jointParameters HingeJointParameters {
          axis 0.000000 1.000000 0.000000
          anchor 0.000000 -0.145000 0.000000
        }
        device [
          RotationalMotor {
            name "right_motor"
            maxTorque 10000
          }
          PositionSensor {
            name "right_motor_sensor"
          }
        ]
        endPoint Solid {
          translation 0.000000 -0.145000 0.000000
          children [
            Pose {
              rotation 0.000000 0.000000 1.000000 3.141590
              children [
                Shape {
                  appearance PBRAppearance {
                    baseColor 0.500000 0.500000 0.500000
                    roughness 1.000000
                    metalness 0
                  }
                  geometry USE wheel
                }
              ]
            }
          ]
          name "right_wheel_link"
          boundingObject Pose {
            translation 0.000000 -0.030000 0.000000
            rotation 1.000000 0.000000 0.000000 1.570700
            children [
              Cylinder {
                radius 0.085
                height 0.03
              }
            ]
          }
          physics Physics {
            density -1
            mass 2.000000
            centerOfMass [ 0.000000 0.000000 0.000000 ]
            inertiaMatrix [
              1.000000e-04 1.000000e-04 1.000000e-04
              0.000000e+00 0.000000e+00 0.000000e+00
            ]
          }
        }
      }
      HingeJoint {
        jointParameters HingeJointParameters {
          axis 0.000000 0.000000 1.000000
          anchor -0.310000 0.000000 0.000000
        }
        device [
          RotationalMotor {
            name "caster_steering_joint"
            maxTorque 10000
          }
          PositionSensor {
            name "caster_steering_joint_sensor"
          }
        ]
        endPoint Solid {
          translation -0.310000 0.000000 0.000000
          children [
            Shape {
              appearance PBRAppearance {
                baseColor 0.500000 0.500000 0.500000
                roughness 1.000000
                metalness 0
              }
              geometry DEF caster_holder Mesh {
                url "/spesbot/ros2_ws/install/spesbot_description/share/spesbot_description/urdf/meshes/caster_holder.stl"
              }
            }
            HingeJoint {
              jointParameters HingeJointParameters {
                axis 0.000000 1.000000 0.000000
                anchor -0.030000 0.000000 -0.050000
              }
              device [
                RotationalMotor {
                  name "caster_wheel_joint"
                  maxTorque 10000
                }
                PositionSensor {
                  name "caster_wheel_joint_sensor"
                }
              ]
              endPoint Solid {
                translation -0.030000 0.000000 -0.050000
                children [
                  Shape {
                    appearance PBRAppearance {
                      baseColor 0.500000 0.500000 0.500000
                      roughness 1.000000
                      metalness 0
                    }
                    geometry DEF caster_wheel Mesh {
                      url "/spesbot/ros2_ws/install/spesbot_description/share/spesbot_description/urdf/meshes/caster_wheel.stl"
                    }
                  }
                ]
                name "caster_wheel_link"
                boundingObject Pose {
                  rotation 1.000000 0.000000 0.000000 1.570700
                  children [
                    Cylinder {
                      radius 0.033
                      height 0.03
                    }
                  ]
                }
                physics Physics {
                  density -1
                  mass 2.000000
                  centerOfMass [ 0.000000 0.000000 0.000000 ]
                  inertiaMatrix [
                    1.000000e-04 1.000000e-04 1.000000e-04
                    0.000000e+00 0.000000e+00 0.000000e+00
                  ]
                }
              }
            }
          ]
          name "caster_holder_link"
          boundingObject Cylinder {
            radius 0.03
            height 0.01
          }
          physics Physics {
            density -1
            mass 0.300000
            centerOfMass [ 0.000000 0.000000 0.000000 ]
            inertiaMatrix [
              1.000000e-04 1.000000e-04 1.000000e-04
              0.000000e+00 0.000000e+00 0.000000e+00
            ]
          }
        }
      }
      Group {
        children IS toolSlot
      }
    ]
    name IS name
    boundingObject Pose {
      translation -0.150000 0.000000 0.000000
      children [
        Box {
           size 0.400000 0.300000 0.020000
        }
      ]
    }
    physics Physics {
      density -1
      mass 5.000000
      centerOfMass [ 0.000000 0.000000 0.000000 ]
      inertiaMatrix [
        1.000000e-01 1.000000e-01 1.000000e-01
        0.000000e+00 0.000000e+00 0.000000e+00
      ]
    }
  }
}
